Workbook

Sheet Resumen
A1: Resumen de pruebas — CultureGo
A4: Ejecución unitaria de referencia (N.º) | C4: 1 | D4: Cambiar al N.º de la última ejecución unitaria registrada en «Ejecuciones».
A6: Pruebas unitarias (ejecución de referencia)
A7: Fecha | C7: =INDEX(Ejecuciones!$B$5:$B$200,MATCH(Resumen!$C$4,Ejecuciones!$A$5:$A$200,0)) -> 11-10-2026
A8: Pruebas ejecutadas | C8: =INDEX(Ejecuciones!$L$5:$L$200,MATCH(Resumen!$C$4,Ejecuciones!$A$5:$A$200,0)) -> 110
A9: Pass | C9: =INDEX(Ejecuciones!$I$5:$I$200,MATCH(Resumen!$C$4,Ejecuciones!$A$5:$A$200,0)) -> 91
A10: Fail | C10: =INDEX(Ejecuciones!$J$5:$J$200,MATCH(Resumen!$C$4,Ejecuciones!$A$5:$A$200,0)) -> 19
A11: % aprobación | C11: =INDEX(Ejecuciones!$M$5:$M$200,MATCH(Resumen!$C$4,Ejecuciones!$A$5:$A$200,0)) -> 0.82727273
A12: Cobertura de líneas global | C12: =INDEX(Ejecuciones!$N$5:$N$200,MATCH(Resumen!$C$4,Ejecuciones!$A$5:$A$200,0)) -> 0.48543689
A14: Pruebas manuales (resultado vigente)
A15: Casos definidos | C15: =COUNTA('Resultados QA'!$Q$5:$Q$33) -> 29
A16: Ejecutados | C16: =C15-COUNTIF('Resultados QA'!$Q$5:$Q$33,"No ejecutado") -> 28
A17: Pass | C17: =COUNTIF('Resultados QA'!$Q$5:$Q$33,"Pass") -> 15
A18: Fail | C18: =COUNTIF('Resultados QA'!$Q$5:$Q$33,"Fail") -> 13
A19: Bloqueados | C19: =COUNTIF('Resultados QA'!$Q$5:$Q$33,"Bloqueado") -> 0
A20: Críticos en Pass (de 13) | C20: =COUNTIFS('Resultados QA'!$D$5:$D$33,"Crítico",'Resultados QA'!$Q$5:$Q$33,"Pass") -> 6
A22: Incidencias
A23: Severidad | B23: Abiertas | C23: Cerradas | D23: Aceptadas | E23: Total
A24: Crítica | B24: =COUNTIFS(Incidencias!$J$5:$J$200,"Crítica",Incidencias!$A$5:$A$200,"<>",Incidencias!$K$5:$K$200,"<>Cerrada",Incidencias!$K$5:$K$200,"<>Aceptada") -> 0 | C24: =COUNTIFS(Incidencias!$J$5:$J$200,"Crítica",Incidencias!$K$5:$K$200,"Cerrada") -> 0 | D24: =COUNTIFS(Incidencias!$J$5:$J$200,"Crítica",Incidencias!$K$5:$K$200,"Aceptada") -> 0 | E24: =SUM(B24:D24) -> 0
A25: Alta | B25: =COUNTIFS(Incidencias!$J$5:$J$200,"Alta",Incidencias!$A$5:$A$200,"<>",Incidencias!$K$5:$K$200,"<>Cerrada",Incidencias!$K$5:$K$200,"<>Aceptada") -> 1 | C25: =COUNTIFS(Incidencias!$J$5:$J$200,"Alta",Incidencias!$K$5:$K$200,"Cerrada") -> 0 | D25: =COUNTIFS(Incidencias!$J$5:$J$200,"Alta",Incidencias!$K$5:$K$200,"Aceptada") -> 0 | E25: =SUM(B25:D25) -> 1
A26: Media | B26: =COUNTIFS(Incidencias!$J$5:$J$200,"Media",Incidencias!$A$5:$A$200,"<>",Incidencias!$K$5:$K$200,"<>Cerrada",Incidencias!$K$5:$K$200,"<>Aceptada") -> 8 | C26: =COUNTIFS(Incidencias!$J$5:$J$200,"Media",Incidencias!$K$5:$K$200,"Cerrada") -> 0 | D26: =COUNTIFS(Incidencias!$J$5:$J$200,"Media",Incidencias!$K$5:$K$200,"Aceptada") -> 0 | E26: =SUM(B26:D26) -> 8
A27: Baja | B27: =COUNTIFS(Incidencias!$J$5:$J$200,"Baja",Incidencias!$A$5:$A$200,"<>",Incidencias!$K$5:$K$200,"<>Cerrada",Incidencias!$K$5:$K$200,"<>Aceptada") -> 10 | C27: =COUNTIFS(Incidencias!$J$5:$J$200,"Baja",Incidencias!$K$5:$K$200,"Cerrada") -> 0 | D27: =COUNTIFS(Incidencias!$J$5:$J$200,"Baja",Incidencias!$K$5:$K$200,"Aceptada") -> 0 | E27: =SUM(B27:D27) -> 10
A28: Total | B28: =SUM(B24:B27) -> 19 | C28: =SUM(C24:C27) -> 0 | D28: =SUM(D24:D27) -> 0 | E28: =SUM(E24:E27) -> 19
A30: Criterios de salida (regla de decisión, plan sección 5.4)
A31: Obligatorios cumplidos (de 6) | C31: =COUNTIFS(Criterios!$B$5:$B$20,"Obligatorio",Criterios!$G$5:$G$20,"Sí") -> 0
A32: Obligatorios no cumplidos o pendientes | C32: =6-C31 -> 6
A33: Deseables bajo el mínimo | C33: =COUNTIFS(Criterios!$B$5:$B$20,"Deseable",Criterios!$G$5:$G$20,"No") -> 5
A34: Deseables pendientes | C34: =COUNTIFS(Criterios!$B$5:$B$20,"Deseable",Criterios!$G$5:$G$20,"Pendiente") -> 3
A35: Resultado preliminar | C35: =IF(C32>0,"No validado",IF(C34>0,"En curso",IF(C33=0,"Validado",IF(C33<=2,"Validado con observaciones","No validado")))) -> No validado
A36: «En curso» indica que aún hay criterios pendientes de evaluar. Mientras algún obligatorio no se cumpla, el resultado es «No validado».

Sheet Instrucciones
A1: Registro de ejecución de pruebas — CultureGo
A2: Complementa al Plan de Pruebas v2.0. El plan define qué se prueba; esta planilla registra qué pasó en cada ejecución.
A4: Hoja | B4: Para qué sirve | C4: Qué se completa
A5: Resumen | B5: Indicadores de la última ejecución, incidencias por severidad y resultado preliminar según la regla de decisión del plan (sección 5.4). | C5: Solo la celda amarilla con el N.º de la ejecución unitaria de referencia. El resto se calcula.
A6: Ejecuciones | B6: Una fila por ejecución, unitaria o manual: fecha, commit, responsable, totales y cobertura. | C6: Agregar una fila por ejecución. En las unitarias, los totales se calculan desde la columna correspondiente de «Resultados UT».
A7: Resultados UT | B7: Resultado de cada prueba unitaria del plan en cada ejecución. | C7: Completar la columna de la nueva ejecución con Pass, Fail o N/A, a partir del log de Karma.
A8: Resultados QA | B8: Resultado de cada caso manual en el ciclo 1 y en la regresión. | C8: Resultado, fecha, ejecutor, dispositivo, evidencia e incidencia de cada caso ejecutado.
A9: Tiempos | B9: Cinco mediciones por operación para el criterio CS-15. | C9: Las mediciones en segundos; el promedio y el cumplimiento se calculan.
A10: Incidencias | B10: Cada caso en Fail genera una incidencia, con su ciclo de vida: Abierta → En corrección → Corregida → Verificada → Cerrada (o Aceptada, con justificación). | C10: Una fila por incidencia; actualizar el estado, el commit de corrección y la ejecución en que se verificó.
A11: Criterios | B11: Estado de cada criterio de salida del plan. | C11: Los valores se calculan cuando es posible; las celdas amarillas se completan a mano.
A12: Cobertura | B12: Cobertura de código por carpeta de cada ejecución unitaria, según el reporte HTML de Karma. | C12: Una fila por carpeta y ejecución con los valores cubiertos y totales; los porcentajes se calculan.
A13: Decisiones | B13: Puntos en que el plan y el código difieren y el equipo debe decidir. | C13: La decisión, la fecha y el responsable.
A15: Convenciones
A16: Celda amarilla | B16: Dato que se completa a mano. Las celdas sin color contienen datos ya registrados o fórmulas.
A17: Resultados | B17: Pass, Fail, Bloqueado (no se pudo ejecutar, con justificación), No ejecutado, N/A (la prueba no existía en esa ejecución).
A18: Fuente | B18: Ejecuciones 0 y 1 cargadas desde el log de Karma (docs/pruebas/evidencias/ut-ejecucion-2026-10-11.txt) y el reporte de cobertura de Karma (coverage/app/index.html).

Sheet Ejecuciones
A1: Ejecuciones
A2: Una fila por ejecución. En las unitarias, Pass/Fail/Bloqueado se calculan desde la columna de esa ejecución en «Resultados UT».
A4: N.º | B4: Fecha | C4: Tipo | D4: Alcance | E4: Rama | F4: Commit | G4: Responsable | H4: Entorno | I4: Pass | J4: Fail | K4: Bloqueado | L4: Total | M4: % aprobación | N4: Cob. líneas global | O4: Cob. ramas global | P4: Cob. líneas core/ | Q4: Evidencia | R4: Observaciones
A5: 0 | B5: 11-10-2026 | C5: Unitaria | D5: Suite existente sin modificar (línea base). | E5: tests-logs | F5: a3b3dfa | H5: Karma + Chrome (Windows 10) | I5: =COUNTIF('Resultados UT'!F$5:F$114,"Pass") -> 24 | J5: =COUNTIF('Resultados UT'!F$5:F$114,"Fail") -> 10 | K5: =COUNTIF('Resultados UT'!F$5:F$114,"Bloqueado") -> 0 | L5: =SUM(I5:K5) -> 34 | M5: =IF(L5=0,"",I5/L5) -> 0.70588235 | Q5: Salida de consola de ng test (no se guardó archivo). | R5: 10 fallas por configuración de las pruebas (H-01 a H-03). Cobertura no medida.
A6: 1 | B6: 11-10-2026 | C6: Unitaria | D6: Casos UT del plan implementados, sin reparar aún la configuración de la suite existente. | E6: tests-logs | F6: a3b3dfa + cambios sin commit | H6: Karma 6.4.4 + Chrome Headless 155 (Windows 10), Node 22.17.1, Angular CLI 20.3.28 | I6: =COUNTIF('Resultados UT'!G$5:G$114,"Pass") -> 91 | J6: =COUNTIF('Resultados UT'!G$5:G$114,"Fail") -> 19 | K6: =COUNTIF('Resultados UT'!G$5:G$114,"Bloqueado") -> 0 | L6: =SUM(I6:K6) -> 110 | M6: =IF(L6=0,"",I6/L6) -> 0.82727273 | N6: =SUMIFS(Cobertura!$I$5:$I$68,Cobertura!$A$5:$A$68,A6)/SUMIFS(Cobertura!$J$5:$J$68,Cobertura!$A$5:$A$68,A6) -> 0.48543689 | O6: =SUMIFS(Cobertura!$E$5:$E$68,Cobertura!$A$5:$A$68,A6)/SUMIFS(Cobertura!$F$5:$F$68,Cobertura!$A$5:$A$68,A6) -> 0.28571429 | P6: =SUMIFS(Cobertura!$I$5:$I$68,Cobertura!$A$5:$A$68,A6,Cobertura!$B$5:$B$68,"src/app/core/*")/SUMIFS(Cobertura!$J$5:$J$68,Cobertura!$A$5:$A$68,A6,Cobertura!$B$5:$B$68,"src/app/core/*") -> 0.61507937 | Q6: docs/pruebas/evidencias/ut-ejecucion-2026-10-11.txt; coverage/app/index.html (no versionado; cifras en la hoja Cobertura) | R6: 7 defectos de la aplicación (H-04 a H-10), 9 fallas de configuración (H-01 a H-03), 2 decisiones pendientes (D-01, D-02) y 1 caso a reformular (UT-MED-06).
A7: 2 | B7: 12-10-2026 | C7: E2E | D7: Casos manuales QA-01 a QA-29 automatizados con Playwright; QA-05 queda manual. | E7: feature/e2e-playwright | F7: 1d11b24 + cambios sin commit (e2e/) | H7: Playwright 1.64.0, Chromium con emulación de Pixel 7, ionic serve; proyecto real de Supabase con datos E2E- | I7: =COUNTIF('Resultados QA'!$F$5:$F$33,"Pass") -> 15 | J7: =COUNTIF('Resultados QA'!$F$5:$F$33,"Fail") -> 13 | K7: =COUNTIF('Resultados QA'!$F$5:$F$33,"Bloqueado") -> 0 | L7: =SUM(I7:K7) -> 28 | M7: =IF(L7=0,"",I7/L7) -> 0.53571429 | Q7: docs/pruebas/evidencias/e2e-2026-10-12/ (resultados.json e index.html); Evidencias_Ejecucion_Pruebas_CultureGo.docx, sección 4 | R7: 8 defectos de la aplicación (H-11 a H-18; H-08 confirmado), 1 defecto de prueba (H-19), 7 decisiones (D-05 a D-11). En el catálogo real hay un lugar llamado «prueba 1» que no es de las pruebas.
A19: Para una nueva ejecución unitaria, copiar las fórmulas de I a M de la fila anterior y cambiar la columna de «Resultados UT» (Ej. 2 = H, Ej. 3 = I, Ej. 4 = J). Para una ejecución manual o E2E, los totales se cuentan desde la columna de resultado de ese ciclo en «Resultados QA» (C1 = F, regresión = L).
A20: Las columnas de cobertura se calculan desde la hoja Cobertura (core/ = carpetas src/app/core/*). En una nueva ejecución, copiar las fórmulas de N a P de la fila anterior.

Sheet Resultados UT
A1: Resultados de pruebas unitarias
A2: Una columna por ejecución. N/A: la prueba no existía en esa ejecución.
A4: ID | B4: Sección del plan | C4: Módulo | D4: Tipo | E4: Archivo de prueba | F4: Ej. 0 | G4: Ej. 1 | H4: Ej. 2 | I4: Ej. 3 | J4: Ej. 4 | K4: Incidencia | L4: Observación
A5: UT-GRD-01 | B5: 3.1 | C5: Guards | D5: Positivo | E5: auth-guard.spec.ts | F5: N/A | G5: Pass
A6: UT-GRD-02 | B6: 3.1 | C6: Guards | D6: Negativo | E6: auth-guard.spec.ts | F6: N/A | G6: Pass
A7: UT-GRD-03 | B7: 3.1 | C7: Guards | D7: Límite | E7: auth-guard.spec.ts | F7: N/A | G7: Pass
A8: UT-GRD-04 | B8: 3.1 | C8: Guards | D8: Negativo | E8: auth-guard.spec.ts | F8: N/A | G8: Fail | K8: H-05
A9: UT-GRD-05 | B9: 3.1 | C9: Guards | D9: Positivo | E9: admin-guard.spec.ts | F9: N/A | G9: Pass
A10: UT-GRD-06 | B10: 3.1 | C10: Guards | D10: Negativo | E10: admin-guard.spec.ts | F10: N/A | G10: Pass
A11: UT-GRD-07 | B11: 3.1 | C11: Guards | D11: Negativo | E11: admin-guard.spec.ts | F11: N/A | G11: Pass
A12: UT-GRD-08 | B12: 3.1 | C12: Guards | D12: Límite | E12: admin-guard.spec.ts | F12: N/A | G12: Pass
A13: UT-AUTH-01 | B13: 3.2 | C13: Auth | D13: Positivo | E13: auth.spec.ts | F13: N/A | G13: Pass
A14: UT-AUTH-02 | B14: 3.2 | C14: Auth | D14: Positivo | E14: auth.spec.ts | F14: N/A | G14: Pass
A15: UT-AUTH-03 | B15: 3.2 | C15: Auth | D15: Límite | E15: auth.spec.ts | F15: N/A | G15: Fail | L15: Decisión pendiente (D-01).
A16: UT-AUTH-04 | B16: 3.2 | C16: Auth | D16: Negativo | E16: auth.spec.ts | F16: N/A | G16: Pass
A17: UT-AUTH-05 | B17: 3.2 | C17: Auth | D17: Negativo | E17: auth.spec.ts | F17: N/A | G17: Fail | K17: H-04
A18: UT-AUTH-06 | B18: 3.2 | C18: Auth | D18: Positivo | E18: auth.spec.ts | F18: N/A | G18: Pass
A19: UT-AUTH-07 | B19: 3.2 | C19: Auth | D19: Negativo | E19: auth.spec.ts | F19: N/A | G19: Pass
A20: UT-AUTH-08 | B20: 3.2 | C20: Auth | D20: Positivo | E20: auth.spec.ts | F20: N/A | G20: Pass
A21: UT-AUTH-09 | B21: 3.2 | C21: Auth | D21: Positivo | E21: auth.spec.ts | F21: N/A | G21: Pass
A22: UT-AUTH-10 | B22: 3.2 | C22: Auth | D22: Límite | E22: auth.spec.ts | F22: N/A | G22: Pass
A23: UT-AUTH-11 | B23: 3.2 | C23: Auth | D23: Positivo | E23: auth.spec.ts | F23: N/A | G23: Pass
A24: UT-AUTH-12 | B24: 3.2 | C24: Auth | D24: Negativo | E24: auth.spec.ts | F24: N/A | G24: Pass
A25: UT-GAM-01 | B25: 3.3 | C25: Gamificacion | D25: Positivo | E25: gamificacion.spec.ts | F25: N/A | G25: Pass
A26: UT-GAM-02 | B26: 3.3 | C26: Gamificacion | D26: Positivo | E26: gamificacion.spec.ts | F26: N/A | G26: Pass
A27: UT-GAM-03 | B27: 3.3 | C27: Gamificacion | D27: Positivo | E27: gamificacion.spec.ts | F27: N/A | G27: Pass
A28: UT-GAM-04 | B28: 3.3 | C28: Gamificacion | D28: Positivo | E28: gamificacion.spec.ts | F28: N/A | G28: Pass
A29: UT-GAM-05 | B29: 3.3 | C29: Gamificacion | D29: Límite | E29: gamificacion.spec.ts | F29: N/A | G29: Pass
... A39: UT-MED-05 | B39: 3.4 | C39: Medallas | D39: Límite | E39: medallas.component.spec.ts | F39: N/A | G39: Pass
A40: UT-MED-06 | B40: 3.4 | C40: Medallas | D40: Límite | E40: medallas.component.spec.ts | F40: N/A | G40: Fail | L40: Caso reformulado en el plan v2.0; el spec debe ajustarse.
A41: UT-MED-07 | B41: 3.4 | C41: Medallas | D41: Negativo | E41: medallas.component.spec.ts | F41: N/A | G41: Fail | K41: H-09
A42: UT-MED-08 | B42: 3.4 | C42: Medallas | D42: Positivo | E42: medallas.component.spec.ts | F42: N/A | G42: Pass
A43: UT-MED-09 | B43: 3.4 | C43: Medallas | D43: Límite | E43: medallas.component.spec.ts | F43: N/A | G43: Fail | L43: Decisión pendiente (D-02).
A44: UT-MED-10 | B44: 3.4 | C44: Medallas | D44: Límite | E44: medallas.component.spec.ts | F44: N/A | G44: Pass
A45: UT-MED-11 | B45: 3.4 | C45: Medallas | D45: Negativo | E45: medallas.component.spec.ts | F45: N/A | G45: Pass
A46: UT-ERR-01 | B46: 3.5 | C46: Traductores de error | D46: Positivo | E46: traducir-error-auth.spec.ts | F46: N/A | G46: Pass
A47: UT-ERR-02 | B47: 3.5 | C47: Traductores de error | D47: Positivo | E47: traducir-error-auth.spec.ts | F47: N/A | G47: Pass
A48: UT-ERR-03 | B48: 3.5 | C48: Traductores de error | D48: Positivo | E48: traducir-error-auth.spec.ts | F48: N/A | G48: Pass
A49: UT-ERR-04 | B49: 3.5 | C49: Traductores de error | D49: Positivo | E49: traducir-error-auth.spec.ts | F49: N/A | G49: Pass
A50: UT-ERR-05 | B50: 3.5 | C50: Traductores de error | D50: Positivo | E50: traducir-error-auth.spec.ts | F50: N/A | G50: Pass
...

Sheet Resultados QA
A1: Resultados de pruebas manuales
A2: Ciclo 1: primera ejecución completa. Regresión: nueva ejecución de los casos Críticos y de los afectados por correcciones.
A4: ID | B4: Sección | C4: Caso | D4: Prioridad | E4: Requisitos | F4: C1 Resultado | G4: C1 Fecha | H4: C1 Ejecutor | I4: C1 Dispositivo / SO | J4: C1 Evidencia | K4: C1 Incidencia | L4: Reg. Resultado | M4: Reg. Fecha | N4: Reg. Ejecutor | O4: Reg. Evidencia | P4: Reg. Incidencia | Q4: Resultado vigente | R4: C1 Resultado obtenido / observación
A5: QA-01 | B5: 4.2 | C5: Registro exitoso | D5: Crítico | E5: RF-01, RF-21 | F5: Fail | G5: 46307 | H5: Playwright (automatizado) | I5: Chromium · emulación Pixel 7 (web) | J5: EV-QA-01 (Evidencias, sección 4) | K5: H-18 | Q5: =IF(L5<>"",L5,IF(F5<>"",F5,"No ejecutado")) -> Fail | R5: El registro se completa y se muestra «Te enviamos un correo para confirmar tu cuenta», pero en 2,4 s (umbral 2 s). Como el proyecto exige confirmar el correo, la cuenta se confirmó con la service role para usarla en QA-07.
A6: QA-02 | B6: 4.2 | C6: Validaciones del registro | D6: Crítico | E6: RF-01, RF-21, RN-01, RN-02 | F6: Fail | G6: 46307 | H6: Playwright (automatizado) | I6: Chromium · emulación Pixel 7 (web) | J6: EV-QA-02 (Evidencias, sección 4) | K6: H-11 | Q6: =IF(L6<>"",L6,IF(F6<>"",F6,"No ejecutado")) -> Fail | R6: Con el correo de U1, la app muestra «Te enviamos un correo para confirmar tu cuenta» en lugar de indicar que el correo ya está registrado. Sin aceptar los términos, el botón «Crear cuenta» queda deshabilitado. Los pasos posteriores a la primera verificación fallida no se evaluaron.
A7: QA-03 | B7: 4.2 | C7: Inicio de sesión correcto e incorrecto | D7: Crítico | E7: RF-02 | F7: Pass | G7: 46307 | H7: Playwright (automatizado) | I7: Chromium · emulación Pixel 7 (web) | J7: EV-QA-03 (Evidencias, sección 4) | Q7: =IF(L7<>"",L7,IF(F7<>"",F7,"No ejecutado")) -> Pass | R7: Con la contraseña incorrecta se muestra «Correo o contraseña incorrectos.»; con la correcta se llega a Inicio con el saludo en menos de 0,9 s.
A8: QA-04 | B8: 4.2 | C8: Persistencia y cierre de sesión | D8: Secundario | E8: RF-02 | F8: Pass | G8: 46307 | H8: Playwright (automatizado) | I8: Chromium · emulación Pixel 7 (web) | J8: EV-QA-04 (Evidencias, sección 4) | Q8: =IF(L8<>"",L8,IF(F8<>"",F8,"No ejecutado")) -> Pass | R8: La sesión se mantiene al recargar. Tras cerrar sesión, abrir Perfil redirige a /auth/login con redirectTo.
A9: QA-05 | B9: 4.2 | C9: Recuperación de contraseña | D9: Secundario | E9: RF-13 | Q9: =IF(L9<>"",L9,IF(F9<>"",F9,"No ejecutado")) -> No ejecutado | R9: No ejecutado: requiere abrir el enlace de un correo real. Pendiente de ejecución manual.
A10: QA-06 | B10: 4.2 | C10: Edición de nombre y términos desde Configuración | D10: Secundario | E10: RF-03, RF-20, RF-21 | F10: Pass | G10: 46307 | H10: Playwright (automatizado) | I10: Chromium · emulación Pixel 7 (web) | J10: EV-QA-06 (Evidencias, sección 4) | Q10: =IF(L10<>"",L10,IF(F10<>"",F10,"No ejecutado")) -> Pass | R10: El nombre se guardó en 1,07 s y se mantuvo al recargar; los Términos se abrieron en 0,26 s.
A11: QA-07 | B11: 4.2 | C11: Eliminación de cuenta | D11: Secundario | E11: RF-22, RN-11 | F11: Fail | G11: 46307 | H11: Playwright (automatizado) | I11: Chromium · emulación Pixel 7 (web) | J11: EV-QA-07 (Evidencias, sección 4) | K11: H-19 | Q11: =IF(L11<>"",L11,IF(F11<>"",F11,"No ejecutado")) -> Fail | R11: Cancelar no eliminó la cuenta. Al confirmar, la app llevó al inicio de sesión y no a Inicio, como suponía la prueba; la prueba se detuvo ahí y no alcanzó a verificar el borrado en la base de datos ni el rechazo del login.
A12: QA-08 | B12: 4.3 | C12: Catálogo y filtros | D12: Crítico | E12: RF-04 a RF-07, RF-12, RNF-01, RNF-03 | F12: Fail | G12: 46307 | H12: Playwright (automatizado) | I12: Chromium · emulación Pixel 7 (web) | J12: EV-QA-08 (Evidencias, sección 4) | K12: H-12, H-18, D-11 | Q12: =IF(L12<>"",L12,IF(F12<>"",F12,"No ejecutado")) -> Fail | R12: El catálogo carga en unos 0,26 s y llega a la ficha de un lugar desde Inicio. Las tarjetas no muestran el tipo y los lugares pagados no indican su condición. El filtro por comuna tardó 1,1 s (umbral 1 s). Sin coincidencias aparece «No encontramos lugares con estos filtros.», con otra redacción que la del plan.
A13: QA-09 | B13: 4.3 | C13: Mapa con marcadores y filtros | D13: Crítico | E13: RF-08, RF-09, RNF-04 | F13: Fail | G13: 46307 | H13: Playwright (automatizado) | I13: Chromium · emulación Pixel 7 (web) | J13: EV-QA-09 (Evidencias, sección 4) | K13: H-16 | Q13: =IF(L13<>"",L13,IF(F13<>"",F13,"No ejecutado")) -> Fail | R13: Los marcadores aparecen en 0,17 s y los filtros se aplican entre 0,12 y 0,24 s. Con una combinación sin coincidencias el mapa queda sin marcadores, pero no se muestra ningún aviso.
A14: QA-10 | B14: 4.3 | C14: Mapa sin permiso de ubicación | D14: Secundario | E14: RF-08, RNF-15 | F14: Fail | G14: 46307 | H14: Playwright (automatizado) | I14: Chromium · emulación Pixel 7 (web) | J14: EV-QA-10 (Evidencias, sección 4) | K14: H-13 | Q14: =IF(L14<>"",L14,IF(F14<>"",F14,"No ejecutado")) -> Fail | R14: Con el permiso denegado, el mapa y el catálogo funcionan, pero la app no muestra un mensaje que explique el uso de la ubicación antes de solicitarla.
A15: QA-11 | B15: 4.4 | C15: Visita sin sesión y retorno tras login | D15: Crítico | E15: RF-14, RF-02 | F15: Pass | G15: 46307 | H15: Playwright (automatizado) | I15: Chromium · emulación Pixel 7 (web) | J15: EV-QA-11 (Evidencias, sección 4) | Q15: =IF(L15<>"",L15,IF(F15<>"",F15,"No ejecutado")) -> Pass | R15: Sin sesión, «Registrar visita» lleva a /auth/login con redirectTo; el intento fallido lo conserva y, tras el login, la app vuelve al detalle de E2E-L1.
A16: QA-12 | B16: 4.4 | C16: redirectTo hacia sitio externo | D16: Secundario | E16: RF-02 | F16: Pass | G16: 46307 | H16: Playwright (automatizado) | I16: Chromium · emulación Pixel 7 (web) | J16: EV-QA-12 (Evidencias, sección 4) | Q16: =IF(L16<>"",L16,IF(F16<>"",F16,"No ejecutado")) -> Pass | R16: Con redirectTo hacia un sitio externo, tras el login la app navega a /tabs/inicio.
A17: QA-13 | B17: 4.4 | C17: Visita fuera del radio | D17: Crítico | E17: RF-14, RN-03 | F17: Pass | G17: 46307 | H17: Playwright (automatizado) | I17: Chromium · emulación Pixel 7 (web) | J17: EV-QA-13 (Evidencias, sección 4) | Q17: =IF(L17<>"",L17,IF(F17<>"",F17,"No ejecutado")) -> Pass | R17: Se muestra «Estás a 5.6 km del lugar. Acércate para registrar tu visita.» y no se crea la visita.
A18: QA-14 | B18: 4.4 | C18: Visita válida, medalla e historial | D18: Crítico | E18: RF-14, RF-15, RF-16, RN-05, RN-06 | F18: Fail | G18: 46307 | H18: Playwright (automatizado) | I18: Chromium · emulación Pixel 7 (web) | J18: EV-QA-14 (Evidencias, sección 4) | K18: H-15 | Q18: =IF(L18<>"",L18,IF(F18<>"",F18,"No ejecutado")) -> Fail | R18: La visita se registra en 0,34 s, la medalla «Explorador urbano» se otorga en la base de datos y aparece en el perfil y en el historial, pero no se notifica al usuario al obtenerla.
A19: QA-15 | B19: 4.4 | C19: Período de enfriamiento | D19: Crítico | E19: RF-14, RN-04 | F19: Pass | G19: 46307 | H19: Playwright (automatizado) | I19: Chromium · emulación Pixel 7 (web) | J19: EV-QA-15 (Evidencias, sección 4) | Q19: =IF(L19<>"",L19,IF(F19<>"",F19,"No ejecutado")) -> Pass | R19: El segundo intento se rechaza por visita reciente; el contador de lugares y las medallas no cambian.
A20: QA-16 | B20: 4.4 | C20: Visita sin permiso de ubicación | D20: Secundario | E20: RF-14 | F20: Pass | G20: 46307 | H20: Playwright (automatizado) | I20: Chromium · emulación Pixel 7 (web) | J20: EV-QA-16 (Evidencias, sección 4) | Q20: =IF(L20<>"",L20,IF(F20<>"",F20,"No ejecutado")) -> Pass | R20: Se muestra «Activa la ubicación para poder registrar tu visita.» y no se crea la visita.
A21: QA-17 | B21: 4.5 | C21: Crear reseña y visibilidad para otros | D21: Secundario | E21: — | F21: Fail | G21: 46307 | H21: Playwright (automatizado) | I21: Chromium · emulación Pixel 7 (web) | J21: EV-QA-17 (Evidencias, sección 4) | K21: D-09 | Q21: =IF(L21<>"",L21,IF(F21<>"",F21,"No ejecutado")) -> Fail | R21: Con el comentario vacío el botón «Publicar reseña» está habilitado: la app marca el comentario como opcional. La reseña válida se publicó y U2 la ve sin opciones para editarla.
A22: QA-18 | B22: 4.5 | C22: Editar reseña propia | D22: Secundario | E22: — | F22: Pass | G22: 46307 | H22: Playwright (automatizado) | I22: Chromium · emulación Pixel 7 (web) | J22: EV-QA-18 (Evidencias, sección 4) | Q22: =IF(L22<>"",L22,IF(F22<>"",F22,"No ejecutado")) -> Pass | R22: La reseña editada muestra los nuevos valores tras recargar y en la base hay una sola fila.
A23: QA-19 | B23: 4.6 | C23: Personalizar y guardar avatar | D23: Secundario | E23: RF-26 | F23: Fail | G23: 46307 | H23: Playwright (automatizado) | I23: Chromium · emulación Pixel 7 (web) | J23: EV-QA-19 (Evidencias, sección 4) | K23: H-14, D-07 | Q23: =IF(L23<>"",L23,IF(F23<>"",F23,"No ejecutado")) -> Fail | R23: El avatar se guarda en 0,2 s y se ve en Perfil, pero no en el encabezado de Inicio. La app ofrece Cabeza, Ojos, Boca y Cuerpo, sin accesorio ni color.
A24: QA-20 | B24: 4.6 | C24: Persistencia del avatar en Supabase | D24: Secundario | E24: RF-26 | F24: Pass | G24: 46307 | H24: Playwright (automatizado) | I24: Chromium · emulación Pixel 7 (web) | J24: EV-QA-20 (Evidencias, sección 4) | Q24: =IF(L24<>"",L24,IF(F24<>"",F24,"No ejecutado")) -> Pass | R24: El avatar se mantiene al borrar el almacenamiento local y en un contexto de navegador nuevo; la fila del avatar en la base coincide. La verificación del color no aplica porque la app no tiene ese control.
A25: QA-21 | B25: 4.6 | C25: Ítems bloqueados y desbloqueados | D25: Secundario | E25: RF-27, RN-14 | F25: Fail | G25: 46307 | H25: Playwright (automatizado) | I25: Chromium · emulación Pixel 7 (web) | J25: EV-QA-21 (Evidencias, sección 4) | K25: D-06 | Q25: =IF(L25<>"",L25,IF(F25<>"",F25,"No ejecutado")) -> Fail | R25: No existen ítems bloqueados ni ítems asociados a medallas; la pantalla indica «Aún no has desbloqueado ninguna recompensa».
A26: QA-22 | B26: 4.7 | C26: Modo oscuro | D26: Secundario | E26: RF-20, RNF-12 | F26: Pass | G26: 46307 | H26: Playwright (automatizado) | I26: Chromium · emulación Pixel 7 (web) | J26: EV-QA-22 (Evidencias, sección 4) | K26: D-11 | Q26: =IF(L26<>"",L26,IF(F26<>"",F26,"No ejecutado")) -> Pass | R26: El modo oscuro se aplica y se mantiene al recargar en ambos sentidos. El interruptor está en Perfil, no en Configuración. La ausencia de destello al reabrir queda como verificación manual.
A27: QA-23 | B27: 4.8 | C27: Acceso restringido al panel | D27: Crítico | E27: RF-10, RNF-07 | F27: Pass | G27: 46307 | H27: Playwright (automatizado) | I27: Chromium · emulación Pixel 7 (web) | J27: EV-QA-23 (Evidencias, sección 4) | K27: D-08 | Q27: =IF(L27<>"",L27,IF(F27<>"",F27,"No ejecutado")) -> Pass | R27: U1 no ve el panel y ADM entra en 0,88 s. U1 termina en Inicio porque adminGuard redirige a /admin/login-admin, ruta que no existe.
A28: QA-24 | B28: 4.8 | C28: Crear lugar y validaciones | D28: Crítico | E28: RF-11, RNF-13 | F28: Fail | G28: 46307 | H28: Playwright (automatizado) | I28: Chromium · emulación Pixel 7 (web) | J28: EV-QA-24 (Evidencias, sección 4) | K28: H-08, H-17 | Q28: =IF(L28<>"",L28,IF(F28<>"",F28,"No ejecutado")) -> Fail | R28: Con el nombre vacío el botón «Crear lugar» queda deshabilitado, pero no se indica qué dato falta. Una latitud de 95 se acepta (H-08). El lugar válido se guarda en 0,12 s y U1 lo ve en el catálogo y en el mapa.
A29: QA-25 | B29: 4.8 | C29: Editar lugar e imagen | D29: Crítico | E29: RF-11, RNF-13 | F29: Pass | G29: 46307 | H29: Playwright (automatizado) | I29: Chromium · emulación Pixel 7 (web) | J29: EV-QA-25 (Evidencias, sección 4) | Q29: =IF(L29<>"",L29,IF(F29<>"",F29,"No ejecutado")) -> Pass | R29: Los cambios de E2E-L1 se reflejan para U1. El PDF se rechaza. La imagen de 3.601.608 bytes se subió con 797.465 bytes (78 % menos). La nitidez queda como verificación manual.
A30: QA-26 | B30: 4.8 | C30: Eliminar lugar | D30: Secundario | E30: RF-11 | F30: Pass | G30: 46307 | H30: Playwright (automatizado) | I30: Chromium · emulación Pixel 7 (web) | J30: EV-QA-26 (Evidencias, sección 4) | Q30: =IF(L30<>"",L30,IF(F30<>"",F30,"No ejecutado")) -> Pass | R30: Se pide confirmación, aparece «Lugar eliminado.» y el lugar desaparece del catálogo y del mapa.
A31: QA-27 | B31: 4.8 | C31: Reportes y Mis tickets | D31: Secundario | E31: RF-17, RF-19, RF-23 | F31: Pass | G31: 46307 | H31: Playwright (automatizado) | I31: Chromium · emulación Pixel 7 (web) | J31: EV-QA-27 (Evidencias, sección 4) | Q31: =IF(L31<>"",L31,IF(F31<>"",F31,"No ejecutado")) -> Pass | R31: El reporte vacío se rechaza y el completo se envía en 0,24 s; ADM lo lleva a «Resuelto» y U1 ve ese estado en «Mis tickets».
A32: QA-28 | B32: 4.8 | C32: Sugerencias y Mis tickets | D32: Secundario | E32: RF-18, RF-19, RF-24, RN-12 | F32: Fail | G32: 46307 | H32: Playwright (automatizado) | I32: Chromium · emulación Pixel 7 (web) | J32: EV-QA-28 (Evidencias, sección 4) | K32: D-10 | Q32: =IF(L32<>"",L32,IF(F32<>"",F32,"No ejecutado")) -> Fail | R32: Las sugerencias se envían (0,85 s y 0,12 s). Aprobar abre «Revisar y publicar», que publica el lugar en el catálogo; la prueba esperaba que la aprobación no creara un lugar y se detuvo en esa verificación.
A33: QA-29 | B33: 4.8 | C33: Protección de rol y RLS vía API | D33: Crítico | E33: RF-25, RNF-07, RN-07, RN-08 | F33: Fail | G33: 46307 | H33: Playwright (automatizado) | I33: Chromium · emulación Pixel 7 (web) | J33: EV-QA-29 (Evidencias, sección 4) | K33: D-05 | Q33: =IF(L33<>"",L33,IF(F33<>"",F33,"No ejecutado")) -> Fail | R33: La API rechaza que U1 se asigne el rol de administrador (HTTP 400, sin filas afectadas) y que cree un lugar (HTTP 403). El panel no tiene una pantalla de gestión de usuarios, por lo que no se pudo verificar la asignación de rol por ADM.

Sheet Tiempos
A1: Mediciones de tiempo de respuesta (criterio CS-15)
A2: Cinco mediciones en segundos por operación, con WiFi o 4G. Se miden durante la ejecución de los casos indicados.
A4: Operación | B4: Requisito | C4: Caso | D4: Umbral (s) | E4: Condición | F4: Med. 1 | G4: Med. 2 | H4: Med. 3 | I4: Med. 4 | J4: Med. 5 | K4: Promedio (s) | L4: Cumple
A5: Carga del catálogo completo | B5: RNF-03 | C5: QA-08 | D5: 3 | E5: ≤ | F5: 0.264 | G5: 0.372 | H5: 0.26 | I5: 0.268 | J5: 0.258 | K5: =IF(COUNT(F5:J5)=0,"",AVERAGE(F5:J5)) -> 0.2844 | L5: =IF(K5="","Pendiente",IF(IF(E5="<",K5<D5,K5<=D5),"Sí","No")) -> Sí
A6: Actualización de marcadores al filtrar el mapa | B6: RNF-04 | C6: QA-09 | D6: 3 | E6: ≤ | F6: 0.237 | G6: 0.119 | H6: 0.145 | I6: 0.124 | J6: 0.141 | K6: =IF(COUNT(F6:J6)=0,"",AVERAGE(F6:J6)) -> 0.1532 | L6: =IF(K6="","Pendiente",IF(IF(E6="<",K6<D6,K6<=D6),"Sí","No")) -> Sí
A7: Creación de cuenta | B7: RF-01 | C7: QA-01 | D7: 2 | E7: ≤ | F7: 2.399 | K7: =IF(COUNT(F7:J7)=0,"",AVERAGE(F7:J7)) -> 2.399 | L7: =IF(K7="","Pendiente",IF(IF(E7="<",K7<D7,K7<=D7),"Sí","No")) -> No
A8: Inicio de sesión | B8: RF-02 | C8: QA-03 | D8: 2 | E8: ≤ | F8: 0.866 | G8: 0.873 | H8: 0.846 | I8: 0.342 | J8: 0.861 | K8: =IF(COUNT(F8:J8)=0,"",AVERAGE(F8:J8)) -> 0.7576 | L8: =IF(K8="","Pendiente",IF(IF(E8="<",K8<D8,K8<=D8),"Sí","No")) -> Sí
A9: Registro de visita | B9: RF-14 | C9: QA-14 | D9: 2 | E9: ≤ | F9: 0.344 | K9: =IF(COUNT(F9:J9)=0,"",AVERAGE(F9:J9)) -> 0.344 | L9: =IF(K9="","Pendiente",IF(IF(E9="<",K9<D9,K9<=D9),"Sí","No")) -> Sí
A11: Fuente de los umbrales: ERS CultureGo v1.0, sección 3.2 (RNF) y fichas RF-01, RF-02 y RF-14.
A12: Mediciones de la ejecución 2 (E2E con Playwright, 12-10-2026). La creación de cuenta y el registro de visita se midieron una sola vez, por el límite de correos de Supabase y el período de enfriamiento de 6 h (celdas en gris).

Sheet Incidencias
A1: Registro de incidencias
A2: Cada caso en Fail genera una incidencia. Se cierra cuando una ejecución posterior lo da como Pass (Verificada → Cerrada).
A4: ID | B4: Fecha detección | C4: Detectada en | D4: Caso(s) | E4: Tipo | F4: Componente / archivo | G4: Descripción | H4: Resultado esperado | I4: Resultado obtenido | J4: Severidad | K4: Estado | L4: Responsable | M4: Fecha cierre | N4: Commit corrección | O4: Verificada en | P4: Observaciones
A5: H-01 | B5: 11-10-2026 | C5: Ej. 0 | D5: UT-SMK-17, UT-SMK-21, UT-CFG-01, UT-CFG-02 | E5: Defecto de prueba | F5: lista-lugares y configuracion (.spec.ts) | G5: El TestBed no provee la navegación de Ionic (NavController) que los componentes usan desde que incorporaron ionViewWillEnter. Bloquea la verificación automática del cambio de contraseña y de nombre. | H5: Las pruebas se ejecutan y evalúan su lógica. | I5: Cannot read properties of undefined (reading 'subscribe') | J5: Media | K5: Abierta | P5: UT-SMK-18 (Medallas) quedó resuelto en la ejecución 1.
A6: H-02 | B6: 11-10-2026 | C6: Ej. 0 | D6: UT-SMK-12, UT-SMK-13, UT-SMK-14, UT-REG-01 | E6: Defecto de prueba | F6: login, recuperar-password y registro (.spec.ts) | G6: El TestBed no provee ActivatedRoute, que los componentes o sus RouterLink requieren. Bloquea la verificación automática de la aceptación de términos. | H6: Las pruebas se ejecutan y evalúan su lógica. | I6: NG0201: No provider found for ActivatedRoute | J6: Media | K6: Abierta
A7: H-03 | B7: 11-10-2026 | C7: Ej. 0 | D7: UT-SMK-26 | E7: Defecto de prueba | F7: tabs.component.spec.ts | G7: El spec declara el componente standalone en declarations e importa IonicModule.forRoot(); debe importarse en imports. | H7: El componente se crea. | I7: TabsComponent is marked as standalone and can't be declared in any NgModule | J7: Baja | K7: Abierta
A8: H-04 | B8: 11-10-2026 | C8: Ej. 1 | D8: UT-AUTH-05 | E8: Defecto de la aplicación | F8: core/services/auth.ts — obtenerUsuarioActual() | G8: Guarda null en caché cuando falla la lectura del perfil (usuarioCache = error ? null : perfil). Un error transitorio hace que la app trate al usuario como sin sesión (guards redirigen al login, perfil vacío) hasta el siguiente evento de autenticación. | H8: El error no queda en caché y la siguiente llamada vuelve a consultar. | I8: La siguiente llamada devuelve null sin consultar. | J8: Alta | K8: Abierta
A9: H-05 | B9: 11-10-2026 | C9: Ej. 1 | D9: UT-GRD-04 | E9: Defecto de la aplicación | F9: core/guards/auth-guard.ts | G9: authGuard no maneja el rechazo de obtenerUsuarioActual(): ante un error de red la navegación termina en excepción. | H9: El guard redirige a /auth/login con redirectTo. | I9: La promesa del guard se rechaza. | J9: Media | K9: Abierta
A10: H-06 | B10: 11-10-2026 | C10: Ej. 1 | D10: UT-ERR-06 | E10: Defecto de la aplicación | F10: core/utils/traducir-error-auth.ts | G10: Solo reconoce «Network request failed»; el error de red del navegador («Failed to fetch») muestra el mensaje genérico. | H10: Mensaje de falta de conexión. | I10: «Ocurrió un error. Intenta de nuevo.» | J10: Media | K10: Abierta
A11: H-07 | B11: 11-10-2026 | C11: Ej. 1 | D11: UT-ERR-07 | E11: Defecto de la aplicación | F11: core/utils/traducir-error-auth.ts | G11: Usa instanceof Error en lugar de duck typing, contra la convención del proyecto. Impacto acotado: los errores de Supabase Auth heredan de Error. | H11: Un objeto plano con message conocido se traduce igual que un Error. | I11: Mensaje genérico. | J11: Baja | K11: Abierta
A12: H-08 | B12: 11-10-2026 | C12: Ej. 1 | D12: UT-CMP-03b, QA-24 | E12: Defecto de la aplicación | F12: features/admin/gestion-lugares | G12: No valida el rango de las coordenadas (latitud −90 a 90, longitud −180 a 180) antes de guardar: un lugar inválido se crea y su marcador no puede ubicarse en el mapa. | H12: No se invoca crearLugar y se indica el dato a corregir. | I12: crearLugar se invoca con latitud 999 y longitud −999. | J12: Media | K12: Abierta | P12: Confirmado en la ejecución 2 (E2E): QA-24 acepta una latitud de 95.
A13: H-09 | B13: 11-10-2026 | C13: Ej. 1 | D13: UT-MED-07 | E13: Defecto de la aplicación | F13: features/gamificacion/medallas | G13: Con cantidad_requerida 0 el progreso de la medalla es NaN (división por cero en el orden y en el ancho de la barra). | H13: Progreso dentro de 0–100 %, sin NaN. | I13: NaN. | J13: Baja | K13: Abierta
A14: H-10 | B14: 11-10-2026 | C14: Ej. 1 | D14: UT-LUG-03 | E14: Defecto de la aplicación | F14: core/services/lugares.ts — listar | G14: Aplica el filtro ilike cuando el texto de búsqueda contiene solo espacios (falta trim antes de la comprobación). | H14: No se aplica ilike. | I14: Se invoca ilike. | J14: Baja | K14: Abierta
A15: H-11 | B15: 12-10-2026 | C15: Ej. 2 | D15: QA-02 | E15: Defecto de la aplicación | F15: features/auth/registro + configuración de Supabase Auth | G15: Registrarse con un correo ya existente muestra «Te enviamos un correo para confirmar tu cuenta». Con la confirmación de correo activa, Supabase responde como si el registro fuera exitoso (para no revelar qué correos existen) y la app no lo detecta (por ejemplo, revisando que user.identities venga vacío). | H15: Mensaje de correo ya registrado; no se crea otra cuenta. | I15: Mensaje de confirmación enviada. | J15: Media | K15: Abierta | P15: RF-01, RN-01.
A16: H-12 | B16: 12-10-2026 | C16: Ej. 2 | D16: QA-08 | E16: Defecto de la aplicación | F16: features/catalogo/lista-lugares (tarjetas) | G16: Las tarjetas del catálogo no muestran el tipo del lugar, y los lugares pagados no indican su condición (solo los gratuitos llevan la etiqueta «Gratis»). | H16: Cada tarjeta muestra nombre, tipo, comuna y gratuidad. | I16: Nombre, comuna y la etiqueta «Gratis» solo en los gratuitos. | J16: Media | K16: Abierta | P16: RF-04.
A17: H-13 | B17: 12-10-2026 | C17: Ej. 2 | D17: QA-10 | E17: Defecto de la aplicación | F17: features/mapa/pagina-mapa | G17: No se muestra un mensaje que explique el uso de la ubicación antes de solicitar el permiso. | H17: Mensaje explicativo previo a la solicitud del permiso. | I17: La solicitud se hace sin mensaje previo. | J17: Media | K17: Abierta | P17: RNF-15 (prioridad alta en la ERS).
A18: H-14 | B18: 12-10-2026 | C18: Ej. 2 | D18: QA-19 | E18: Defecto de la aplicación | F18: features/inicio/pagina-inicio (encabezado) | G18: El avatar guardado se ve en Perfil, pero el encabezado de Inicio sigue mostrando el logo. | H18: El avatar actualizado se ve en Perfil y en Inicio. | I18: Solo se ve en Perfil. | J18: Baja | K18: Abierta | P18: RF-26.
A19: H-15 | B19: 12-10-2026 | C19: Ej. 2 | D19: QA-14 | E19: Defecto de la aplicación | F19: features/catalogo/detalle-lugar (registro de visita) | G19: La medalla se otorga en la base de datos, pero la app no notifica al usuario al obtenerla. | H19: Notificación de la medalla obtenida en ≤ 1 s. | I19: Sin notificación; la medalla solo aparece en Perfil e Historial. | J19: Baja | K19: Abierta | P19: RF-15.
A20: H-16 | B20: 12-10-2026 | C20: Ej. 2 | D20: QA-09 | E20: Defecto de la aplicación | F20: features/mapa/pagina-mapa | G20: Con una combinación de filtros sin coincidencias, el mapa queda sin marcadores y sin aviso. | H20: Aviso al usuario cuando ningún lugar cumple los filtros. | I20: Mapa vacío sin aviso. | J20: Baja | K20: Abierta | P20: RF-09.
A21: H-17 | B21: 12-10-2026 | C21: Ej. 2 | D21: QA-24 | E21: Defecto de la aplicación | F21: features/admin/gestion-lugares (formulario) | G21: Con datos obligatorios faltantes el botón «Crear lugar» se deshabilita, pero no se indica qué dato falta. | H21: Se indica qué dato corregir. | I21: Solo el botón deshabilitado. | J21: Baja | K21: Abierta | P21: RF-11.
A22: H-18 | B22: 12-10-2026 | C22: Ej. 2 | D22: QA-01, QA-08 | E22: Defecto de la aplicación | F22: Registro y filtro por comuna del catálogo | G22: Dos tiempos sobre el umbral de la ERS: creación de cuenta en 2,4 s (≤ 2 s) y filtro del catálogo por comuna en 1,1 s (≤ 1 s). Es una sola medición en cada caso y la primera incluye el envío del correo de confirmación. | H22: Creación de cuenta ≤ 2 s; filtro ≤ 1 s. | I22: 2,4 s y 1,1 s. | J22: Baja | K22: Abierta | P22: Volver a medir antes de corregir; puede ser variación de red.
A23: H-19 | B23: 12-10-2026 | C23: Ej. 2 | D23: QA-07 | E23: Defecto de prueba | F23: e2e/auth.e2e.ts | G23: La prueba espera llegar a Inicio después de eliminar la cuenta, pero la app lleva al inicio de sesión (comportamiento razonable). La prueba se detiene ahí y no verifica el borrado en la base ni el rechazo del login. | H23: La prueba verifica el borrado y el rechazo del login. | I23: Prueba detenida antes de esas verificaciones. | J23: Baja | K23: Abierta | P23: Ajustar la expectativa y volver a ejecutar.
A24: H-20
A25: H-21
A26: H-22
A27: H-23
A28: H-24
A29: H-25
A30: H-26
A31: H-27
A32: H-28
A33: H-29
A34: H-30
A35: H-31
... A38: H-34

Sheet Cobertura
A1: Cobertura de código por carpeta
A2: Valores de coverage/app/index.html (Karma). Una fila por carpeta y ejecución; el reporte HTML no se versiona, por eso se transcribe aquí.
A4: Ejecución | B4: Carpeta | C4: Sent. cubiertas | D4: Sent. totales | E4: Ramas cubiertas | F4: Ramas totales | G4: Func. cubiertas | H4: Func. totales | I4: Líneas cubiertas | J4: Líneas totales | K4: % sentencias | L4: % ramas | M4: % funciones | N4: % líneas
A5: 1 | B5: src | C5: 2 | D5: 2 | E5: 0 | F5: 0 | G5: 0 | H5: 0 | I5: 2 | J5: 2 | K5: =IF(D5=0,"",C5/D5) -> 1 | L5: =IF(F5=0,"",E5/F5) | M5: =IF(H5=0,"",G5/H5) | N5: =IF(J5=0,"",I5/J5) -> 1
A6: 1 | B6: src/app | C6: 1 | D6: 1 | E6: 0 | F6: 0 | G6: 1 | H6: 1 | I6: 1 | J6: 1 | K6: =IF(D6=0,"",C6/D6) -> 1 | L6: =IF(F6=0,"",E6/F6) | M6: =IF(H6=0,"",G6/H6) -> 1 | N6: =IF(J6=0,"",I6/J6) -> 1
A7: 1 | B7: src/app/core/guards | C7: 14 | D7: 14 | E7: 2 | F7: 2 | G7: 2 | H7: 2 | I7: 12 | J7: 12 | K7: =IF(D7=0,"",C7/D7) -> 1 | L7: =IF(F7=0,"",E7/F7) -> 1 | M7: =IF(H7=0,"",G7/H7) -> 1 | N7: =IF(J7=0,"",I7/J7) -> 1
A8: 1 | B8: src/app/core/services | C8: 146 | D8: 261 | E8: 32 | F8: 80 | G8: 33 | H8: 61 | I8: 118 | J8: 196 | K8: =IF(D8=0,"",C8/D8) -> 0.55938697 | L8: =IF(F8=0,"",E8/F8) -> 0.4 | M8: =IF(H8=0,"",G8/H8) -> 0.54098361 | N8: =IF(J8=0,"",I8/J8) -> 0.60204082
A9: 1 | B9: src/app/core/utils | C9: 28 | D9: 50 | E9: 11 | F9: 16 | G9: 5 | H9: 7 | I9: 25 | J9: 44 | K9: =IF(D9=0,"",C9/D9) -> 0.56 | L9: =IF(F9=0,"",E9/F9) -> 0.6875 | M9: =IF(H9=0,"",G9/H9) -> 0.71428571 | N9: =IF(J9=0,"",I9/J9) -> 0.56818182
A10: 1 | B10: src/app/features/admin/gestion-lugares | C10: 54 | D10: 182 | E10: 21 | F10: 74 | G10: 8 | H10: 39 | I10: 53 | J10: 167 | K10: =IF(D10=0,"",C10/D10) -> 0.2967033 | L10: =IF(F10=0,"",E10/F10) -> 0.28378378 | M10: =IF(H10=0,"",G10/H10) -> 0.20512821 | N10: =IF(J10=0,"",I10/J10) -> 0.31736527
A11: 1 | B11: src/app/features/auth/login | C11: 1 | D11: 26 | E11: 0 | F11: 11 | G11: 0 | H11: 7 | I11: 1 | J11: 23 | K11: =IF(D11=0,"",C11/D11) -> 0.038461538 | L11: =IF(F11=0,"",E11/F11) -> 0 | M11: =IF(H11=0,"",G11/H11) -> 0 | N11: =IF(J11=0,"",I11/J11) -> 0.043478261
A12: 1 | B12: src/app/features/auth/recuperar-password | C12: 8 | D12: 18 | E12: 0 | F12: 3 | G12: 1 | H12: 3 | I12: 8 | J12: 17 | K12: =IF(D12=0,"",C12/D12) -> 0.44444444 | L12: =IF(F12=0,"",E12/F12) -> 0 | M12: =IF(H12=0,"",G12/H12) -> 0.33333333 | N12: =IF(J12=0,"",I12/J12) -> 0.47058824
A13: 1 | B13: src/app/features/auth/registro | C13: 17 | D13: 42 | E13: 0 | F13: 16 | G13: 1 | H13: 10 | I13: 16 | J13: 39 | K13: =IF(D13=0,"",C13/D13) -> 0.4047619 | L13: =IF(F13=0,"",E13/F13) -> 0 | M13: =IF(H13=0,"",G13/H13) -> 0.1 | N13: =IF(J13=0,"",I13/J13) -> 0.41025641
A14: 1 | B14: src/app/features/auth/restablecer-password | C14: 16 | D14: 29 | E14: 3 | F14: 11 | G14: 3 | H14: 6 | I14: 15 | J14: 27 | K14: =IF(D14=0,"",C14/D14) -> 0.55172414 | L14: =IF(F14=0,"",E14/F14) -> 0.27272727 | M14: =IF(H14=0,"",G14/H14) -> 0.5 | N14: =IF(J14=0,"",I14/J14) -> 0.55555556
A15: 1 | B15: src/app/features/catalogo/detalle-lugar | C15: 102 | D15: 151 | E15: 21 | F15: 46 | G15: 16 | H15: 31 | I15: 99 | J15: 144 | K15: =IF(D15=0,"",C15/D15) -> 0.67549669 | L15: =IF(F15=0,"",E15/F15) -> 0.45652174 | M15: =IF(H15=0,"",G15/H15) -> 0.51612903 | N15: =IF(J15=0,"",I15/J15) -> 0.6875
A16: 1 | B16: src/app/features/catalogo/lista-lugares | C16: 16 | D16: 46 | E16: 0 | F16: 15 | G16: 1 | H16: 15 | I16: 16 | J16: 45 | K16: =IF(D16=0,"",C16/D16) -> 0.34782609 | L16: =IF(F16=0,"",E16/F16) -> 0 | M16: =IF(H16=0,"",G16/H16) -> 0.066666667 | N16: =IF(J16=0,"",I16/J16) -> 0.35555556
... A28: 1 | B28: src/environments | C28: 1 | D28: 1 | E28: 0 | F28: 0 | G28: 0 | H28: 0 | I28: 1 | J28: 1 | K28: =IF(D28=0,"",C28/D28) -> 1 | L28: =IF(F28=0,"",E28/F28) | M28: =IF(H28=0,"",G28/H28) | N28: =IF(J28=0,"",I28/J28) -> 1
K29: =IF(OR(D29="",D29=0),"",C29/D29) | L29: =IF(OR(F29="",F29=0),"",E29/F29) | M29: =IF(OR(H29="",H29=0),"",G29/H29) | N29: =IF(OR(J29="",J29=0),"",I29/J29)
K30: =IF(OR(D30="",D30=0),"",C30/D30) | L30: =IF(OR(F30="",F30=0),"",E30/F30) | M30: =IF(OR(H30="",H30=0),"",G30/H30) | N30: =IF(OR(J30="",J30=0),"",I30/J30)
K31: =IF(OR(D31="",D31=0),"",C31/D31) | L31: =IF(OR(F31="",F31=0),"",E31/F31) | M31: =IF(OR(H31="",H31=0),"",G31/H31) | N31: =IF(OR(J31="",J31=0),"",I31/J31)
K32: =IF(OR(D32="",D32=0),"",C32/D32) | L32: =IF(OR(F32="",F32=0),"",E32/F32) | M32: =IF(OR(H32="",H32=0),"",G32/H32) | N32: =IF(OR(J32="",J32=0),"",I32/J32)
K33: =IF(OR(D33="",D33=0),"",C33/D33) | L33: =IF(OR(F33="",F33=0),"",E33/F33) | M33: =IF(OR(H33="",H33=0),"",G33/H33) | N33: =IF(OR(J33="",J33=0),"",I33/J33)
K34: =IF(OR(D34="",D34=0),"",C34/D34) | L34: =IF(OR(F34="",F34=0),"",E34/F34) | M34: =IF(OR(H34="",H34=0),"",G34/H34) | N34: =IF(OR(J34="",J34=0),"",I34/J34)
K35: =IF(OR(D35="",D35=0),"",C35/D35) | L35: =IF(OR(F35="",F35=0),"",E35/F35) | M35: =IF(OR(H35="",H35=0),"",G35/H35) | N35: =IF(OR(J35="",J35=0),"",I35/J35)
K36: =IF(OR(D36="",D36=0),"",C36/D36) | L36: =IF(OR(F36="",F36=0),"",E36/F36) | M36: =IF(OR(H36="",H36=0),"",G36/H36) | N36: =IF(OR(J36="",J36=0),"",I36/J36)
K37: =IF(OR(D37="",D37=0),"",C37/D37) | L37: =IF(OR(F37="",F37=0),"",E37/F37) | M37: =IF(OR(H37="",H37=0),"",G37/H37) | N37: =IF(OR(J37="",J37=0),"",I37/J37)
K38: =IF(OR(D38="",D38=0),"",C38/D38) | L38: =IF(OR(F38="",F38=0),"",E38/F38) | M38: =IF(OR(H38="",H38=0),"",G38/H38) | N38: =IF(OR(J38="",J38=0),"",I38/J38)
K39: =IF(OR(D39="",D39=0),"",C39/D39) | L39: =IF(OR(F39="",F39=0),"",E39/F39) | M39: =IF(OR(H39="",H39=0),"",G39/H39) | N39: =IF(OR(J39="",J39=0),"",I39/J39)
K40: =IF(OR(D40="",D40=0),"",C40/D40) | L40: =IF(OR(F40="",F40=0),"",E40/F40) | M40: =IF(OR(H40="",H40=0),"",G40/H40) | N40: =IF(OR(J40="",J40=0),"",I40/J40)
... K68: =IF(OR(D68="",D68=0),"",C68/D68) | L68: =IF(OR(F68="",F68=0),"",E68/F68) | M68: =IF(OR(H68="",H68=0),"",G68/H68) | N68: =IF(OR(J68="",J68=0),"",I68/J68)
A70: Solo aparecen los archivos importados por algún .spec.ts; los componentes sin prueba no entran en el cálculo de Karma.

Sheet Decisiones
A1: Decisiones pendientes
A2: Diferencias entre el plan y el código que el equipo debe resolver. Al decidir, se ajusta el código (y se registra una incidencia) o el plan (y se sube su versión).
A4: ID | B4: Origen | C4: Tema | D4: Opciones | E4: Recomendación | F4: Decisión | G4: Fecha | H4: Responsable
A5: D-01 | B5: UT-AUTH-03 | C5: Dos llamadas simultáneas a obtenerUsuarioActual() hacen dos consultas, porque la caché guarda el valor y no la promesa en curso. | D5: A) Guardar la promesa en curso (el caso pasa). B) Aceptar el comportamiento y cambiar el caso para documentarlo. | E5: A, si se corrige H-04 al mismo tiempo: ambos cambios tocan el mismo método.
A6: D-02 | B6: UT-MED-09 | C6: Dos medallas no obtenidas con igual porcentaje no se desempatan: quedan en el orden de llegada. | D6: A) Agregar desempate por cantidad requerida ascendente (el caso pasa). B) Aceptar el orden actual y cambiar el caso. | E6: A: es una línea en el sort y hace el orden determinista.
A7: D-03 | B7: ERS v1.0, 1.2 | C7: La ERS declara las reseñas fuera de alcance, pero están implementadas y el plan las prueba (QA-17 y QA-18). | D7: A) Agregar un RF de reseñas a la ERS. B) Retirar las reseñas del producto y del plan. | E7: A, si las reseñas se mantienen en el producto.
A8: D-04 | B8: UT-SUP-01 | C8: El spec de Supabase crea el cliente real con la URL del proyecto (genera la advertencia «Multiple GoTrueClient instances»). El plan pide datos ficticios. | D8: A) Usar un environment de prueba con URL y clave ficticias. B) Mantenerlo y documentar la excepción. | E8: A.
A9: D-05 | B9: QA-29, RF-25 | C9: El panel no tiene gestión de usuarios y roles (RF-25, prioridad baja). La protección del rol en la API sí funciona. | D9: A) Implementar una pantalla mínima de usuarios y roles. B) Ajustar la ERS: el rol se asigna desde Supabase y RF-25 queda fuera del alcance de esta versión. | E9: B, dada la prioridad baja, salvo que el docente lo exija.
A10: D-06 | B10: QA-21, RF-27 | C10: No existen ítems de avatar asociados a medallas: RF-27 no está implementado, aunque la pantalla ya muestra un aviso de recompensas. | D10: A) Implementar el desbloqueo con al menos un ítem por medalla. B) Ajustar la ERS y dejar RF-27 para una versión futura. | E10: A, si el tiempo alcanza: la interfaz ya lo anticipa.
A11: D-07 | B11: QA-19, RF-26 | C11: El avatar tiene Cabeza, Ojos, Boca y Cuerpo, sin accesorio ni color; la ERS y el plan describen boca, ojos, accesorio y ropa o cuerpo, y el plan agrega color. | D11: A) Ajustar la ERS y el plan a los componentes reales. B) Agregar accesorio y color a la app. | E11: A.
A12: D-08 | B12: QA-23, RF-10 | C12: adminGuard redirige a /admin/login-admin, ruta que no existe; no hay un acceso de administración separado y ADM entra con el login normal. | D12: A) Redirigir a /auth/login con redirectTo o a Inicio, y ajustar UT-GRD-06/07. B) Crear la pantalla de acceso de administración. | E12: A.
A13: D-09 | B13: QA-17 | C13: La app permite publicar una reseña sin comentario y lo señala como «(opcional)»; el plan esperaba que fuera obligatorio. | D13: A) Aceptar el comentario como opcional y ajustar QA-17. B) Hacerlo obligatorio en la app. | E13: A: la interfaz lo declara opcional.
A14: D-10 | B14: QA-28, RN-12 | C14: Aprobar una sugerencia abre «Revisar y publicar», donde ADM completa y publica el lugar. Es coherente con RN-12 (la publicación la hace el administrador), pero QA-28 esperaba que la aprobación no creara un lugar. | D14: A) Ajustar QA-28: la aprobación publica mediante el formulario del CRUD. B) Separar «aprobar» de «publicar» en la app. | E14: A.
A15: D-11 | B15: QA-08, QA-22 | C15: Diferencias de redacción entre el plan y la app: el mensaje sin coincidencias del catálogo dice «No encontramos lugares con estos filtros.» y el interruptor de modo oscuro está en Perfil, no en Configuración. | D15: A) Ajustar el plan y las pruebas a la app. | E15: A.

Sheet Criterios
A1: Estado de los criterios de salida
A2: Plan de Pruebas v2.0, sección 5.3. Los valores calculados toman la ejecución unitaria indicada en «Resumen».
A4: ID | B4: Tipo | C4: Criterio | D4: Meta | E4: Mínimo aceptable | F4: Valor actual | G4: ¿Cumple el mínimo? | H4: Cómo se obtiene
A5: CS-01 | B5: Obligatorio | C5: Suite unitaria completa ejecutada | D5: 100 % | E5: 100 % | F5: Parcial | G5: Pendiente | H5: Manual: Sí cuando la ejecución de referencia incluye todos los casos UT del plan y H-01 a H-03 están cerradas.
A6: CS-02 | B6: Obligatorio | C6: Suite unitaria sin fallas no justificadas | D6: 0 | E6: 0 | F6: =INDEX(Ejecuciones!$J$5:$J$200,MATCH(Resumen!$C$4,Ejecuciones!$A$5:$A$200,0)) -> 19 | G6: =IF(F6="","Pendiente",IF(F6=0,"Sí","No")) -> No | H6: Fail de la ejecución de referencia (hoja Ejecuciones).
A7: CS-03 | B7: Obligatorio | C7: Casos manuales críticos aprobados | D7: 100 % | E7: 100 % | F7: =COUNTIFS('Resultados QA'!$D$5:$D$33,"Crítico",'Resultados QA'!$Q$5:$Q$33,"Pass")/COUNTIF('Resultados QA'!$D$5:$D$33,"Crítico") -> 0.46153846 | G7: =IF(F7=1,"Sí",IF(COUNTIFS('Resultados QA'!$D$5:$D$33,"Crítico",'Resultados QA'!$Q$5:$Q$33,"No ejecutado")>0,"Pendiente","No")) -> No | H7: Críticos en Pass / 13 (hoja Resultados QA, resultado vigente).
A8: CS-04 | B8: Obligatorio | C8: Control de acceso verificado | D8: Cumple | E8: Cumple | F8: =IF(AND('Resultados QA'!$Q$27="Pass",'Resultados QA'!$Q$33="Pass"),"Cumple",IF(OR('Resultados QA'!$Q$27="No ejecutado",'Resultados QA'!$Q$33="No ejecutado"),"Pendiente","No cumple")) -> No cumple | G8: =IF(F8="Cumple","Sí",IF(OR('Resultados QA'!$Q$27="No ejecutado",'Resultados QA'!$Q$33="No ejecutado"),"Pendiente","No")) -> No | H8: QA-23 y QA-29 en Pass.
A9: CS-05 | B9: Obligatorio | C9: Sin incidencias críticas ni altas abiertas | D9: 0 | E9: 0 | F9: =COUNTIFS(Incidencias!$J$5:$J$200,"Crítica",Incidencias!$A$5:$A$200,"<>",Incidencias!$K$5:$K$200,"<>Cerrada",Incidencias!$K$5:$K$200,"<>Aceptada")+COUNTIFS(Incidencias!$J$5:$J$200,"Alta",Incidencias!$A$5:$A$200,"<>",Incidencias!$K$5:$K$200,"<>Cerrada",Incidencias!$K$5:$K$200,"<>Aceptada") -> 1 | G9: =IF(F9=0,"Sí","No") -> No | H9: Incidencias Crítica o Alta en estado distinto de Cerrada o Aceptada.
A10: CS-06 | B10: Obligatorio | C10: Requisitos de prioridad alta validados | D10: 100 % | E10: 100 % | G10: Pendiente | H10: Manual: revisar la matriz de cobertura del plan (sección 4.9) contra los resultados.
A11: CS-07 | B11: Deseable | C11: Aprobación global de casos manuales | D11: ≥ 95 % | E11: ≥ 90 % | F11: =IFERROR(COUNTIF('Resultados QA'!$Q$5:$Q$33,"Pass")/(COUNTIF('Resultados QA'!$Q$5:$Q$33,"Pass")+COUNTIF('Resultados QA'!$Q$5:$Q$33,"Fail")),"") -> 0.53571429 | G11: =IF(F11="","Pendiente",IF(F11>=0.9,"Sí","No")) -> No | H11: Pass / (Pass + Fail) en el resultado vigente.
A12: CS-08 | B12: Deseable | C12: Casos manuales ejecutados | D12: 100 % | E12: ≥ 95 % | F12: =(COUNTA('Resultados QA'!$Q$5:$Q$33)-COUNTIF('Resultados QA'!$Q$5:$Q$33,"No ejecutado"))/COUNTA('Resultados QA'!$Q$5:$Q$33) -> 0.96551724 | G12: =IF(F12>=0.95,"Sí",IF(F12=0,"Pendiente","No")) -> Sí | H12: Casos con resultado distinto de No ejecutado / 29.
A13: CS-09 | B13: Deseable | C13: Incidencias medias resueltas | D13: Todas cerradas | E13: Todas cerradas o aceptadas; máximo 3 aceptadas | F13: =COUNTIFS(Incidencias!$J$5:$J$200,"Media",Incidencias!$A$5:$A$200,"<>",Incidencias!$K$5:$K$200,"<>Cerrada",Incidencias!$K$5:$K$200,"<>Aceptada") -> 8 | G13: =IF(AND(F13=0,COUNTIFS(Incidencias!$J$5:$J$200,"Media",Incidencias!$K$5:$K$200,"Aceptada")<=3),"Sí","No") -> No | H13: Medias no cerradas ni aceptadas (valor actual) y máximo 3 aceptadas.
A14: CS-10 | B14: Deseable | C14: Incidencias bajas gestionadas | D14: Todas cerradas | E14: Todas documentadas | F14: =COUNTIFS(Incidencias!$J$5:$J$200,"Baja",Incidencias!$A$5:$A$200,"<>",Incidencias!$K$5:$K$200,"<>Cerrada",Incidencias!$K$5:$K$200,"<>Aceptada") -> 10 | G14: Pendiente | H14: Manual: Sí si las bajas abiertas están descritas como riesgo residual en el informe.
A15: CS-11 | B15: Deseable | C15: Cobertura de líneas en core/ | D15: ≥ 75 % | E15: ≥ 60 % | F15: =INDEX(Ejecuciones!$P$5:$P$200,MATCH(Resumen!$C$4,Ejecuciones!$A$5:$A$200,0)) -> 0.61507937 | G15: =IF(F15="","Pendiente",IF(F15>=0.6,"Sí","No")) -> Sí | H15: Cob. líneas core/ de la ejecución de referencia.
A16: CS-12 | B16: Deseable | C16: Cobertura de líneas global | D16: ≥ 55 % | E16: ≥ 50 % | F16: =INDEX(Ejecuciones!$N$5:$N$200,MATCH(Resumen!$C$4,Ejecuciones!$A$5:$A$200,0)) -> 0.48543689 | G16: =IF(F16="","Pendiente",IF(F16>=0.5,"Sí","No")) -> No | H16: Cob. líneas global de la ejecución de referencia.
A17: CS-13 | B17: Deseable | C17: Cobertura de ramas global | D17: ≥ 35 % | E17: ≥ 30 % | F17: =INDEX(Ejecuciones!$O$5:$O$200,MATCH(Resumen!$C$4,Ejecuciones!$A$5:$A$200,0)) -> 0.28571429 | G17: =IF(F17="","Pendiente",IF(F17>=0.3,"Sí","No")) -> No | H17: Cob. ramas global de la ejecución de referencia.
A18: CS-14 | B18: Deseable | C18: Requisitos de prioridad media y baja validados | D18: 100 % | E18: ≥ 85 % | G18: Pendiente | H18: Manual: revisar la matriz de cobertura del plan (sección 4.9).
A19: CS-15 | B19: Deseable | C19: Tiempos de respuesta | D19: Todos los promedios dentro del umbral | E19: Todos los promedios dentro del umbral; se admiten mediciones individuales sobre el umbral | F19: =COUNTIF(Tiempos!$L$5:$L$9,"Sí")&" de 5 dentro del umbral" -> 4 de 5 dentro del umbral | G19: =IF(COUNTIF(Tiempos!$L$5:$L$9,"Sí")=5,"Sí",IF(COUNTIF(Tiempos!$L$5:$L$9,"No")>0,"No","Pendiente")) -> No | H19: Hoja Tiempos.
A20: CS-16 | B20: Deseable | C20: Compatibilidad | D20: 2 versiones recientes de Android e iOS | E20: 1 versión reciente de Android y navegador de escritorio; iOS declarado como limitación si no hay dispositivo | G20: Pendiente | H20: Manual: dispositivos registrados en C1 Dispositivo / SO.
